[2024-09-30T09:48:24.965+0000] {taskinstance.py:1083} INFO - Dependencies all met for <TaskInstance: music_recommendation_system.create_user_genre_matrix scheduled__2024-09-30T09:42:16.484298+00:00 [queued]>
[2024-09-30T09:48:24.980+0000] {taskinstance.py:1083} INFO - Dependencies all met for <TaskInstance: music_recommendation_system.create_user_genre_matrix scheduled__2024-09-30T09:42:16.484298+00:00 [queued]>
[2024-09-30T09:48:24.980+0000] {taskinstance.py:1279} INFO - 
--------------------------------------------------------------------------------
[2024-09-30T09:48:24.981+0000] {taskinstance.py:1280} INFO - Starting attempt 2 of 2
[2024-09-30T09:48:24.982+0000] {taskinstance.py:1281} INFO - 
--------------------------------------------------------------------------------
[2024-09-30T09:48:25.008+0000] {taskinstance.py:1300} INFO - Executing <Task(PythonOperator): create_user_genre_matrix> on 2024-09-30 09:42:16.484298+00:00
[2024-09-30T09:48:25.018+0000] {standard_task_runner.py:55} INFO - Started process 1507 to run task
[2024-09-30T09:48:25.023+0000] {standard_task_runner.py:82} INFO - Running: ['***', 'tasks', 'run', 'music_recommendation_system', 'create_user_genre_matrix', 'scheduled__2024-09-30T09:42:16.484298+00:00', '--job-id', '138', '--raw', '--subdir', 'DAGS_FOLDER/music_recommendation_retraining.py', '--cfg-path', '/tmp/tmpapt3ypq8']
[2024-09-30T09:48:25.030+0000] {standard_task_runner.py:83} INFO - Job 138: Subtask create_user_genre_matrix
[2024-09-30T09:48:25.060+0000] {logging_mixin.py:137} WARNING - /home/***/.local/lib/python3.7/site-packages/***/settings.py:249 DeprecationWarning: The sql_alchemy_conn option in [core] has been moved to the sql_alchemy_conn option in [database] - the old setting has been used, but please update your config.
[2024-09-30T09:48:25.114+0000] {logging_mixin.py:137} WARNING - /home/***/.local/lib/python3.7/site-packages/***/utils/sqlalchemy.py:124 DeprecationWarning: The sql_alchemy_conn option in [core] has been moved to the sql_alchemy_conn option in [database] - the old setting has been used, but please update your config.
[2024-09-30T09:48:25.177+0000] {task_command.py:388} INFO - Running <TaskInstance: music_recommendation_system.create_user_genre_matrix scheduled__2024-09-30T09:42:16.484298+00:00 [running]> on host 1adfe0f4f205
[2024-09-30T09:48:25.423+0000] {taskinstance.py:1509} INFO - Exporting the following env vars:
AIRFLOW_CTX_DAG_OWNER=***
AIRFLOW_CTX_DAG_ID=music_recommendation_system
AIRFLOW_CTX_TASK_ID=create_user_genre_matrix
AIRFLOW_CTX_EXECUTION_DATE=2024-09-30T09:42:16.484298+00:00
AIRFLOW_CTX_TRY_NUMBER=2
AIRFLOW_CTX_DAG_RUN_ID=scheduled__2024-09-30T09:42:16.484298+00:00
[2024-09-30T09:48:25.447+0000] {taskinstance.py:1768} ERROR - Task failed with exception
Traceback (most recent call last):
  File "/home/airflow/.local/lib/python3.7/site-packages/pandas/core/indexes/base.py", line 3361, in get_loc
    return self._engine.get_loc(casted_key)
  File "pandas/_libs/index.pyx", line 76, in pandas._libs.index.IndexEngine.get_loc
  File "pandas/_libs/index.pyx", line 108, in pandas._libs.index.IndexEngine.get_loc
  File "pandas/_libs/hashtable_class_helper.pxi", line 5198, in pandas._libs.hashtable.PyObjectHashTable.get_item
  File "pandas/_libs/hashtable_class_helper.pxi", line 5206, in pandas._libs.hashtable.PyObjectHashTable.get_item
KeyError: 'artist_genres'

The above exception was the direct cause of the following exception:

Traceback (most recent call last):
  File "/home/airflow/.local/lib/python3.7/site-packages/airflow/operators/python.py", line 175, in execute
    return_value = self.execute_callable()
  File "/home/airflow/.local/lib/python3.7/site-packages/airflow/operators/python.py", line 192, in execute_callable
    return self.python_callable(*self.op_args, **self.op_kwargs)
  File "/opt/airflow/dags/music_recommendation_retraining.py", line 79, in create_user_genre_matrix_task
    all_genres = set([genre for genres in df['artist_genres'] for genre in genres])
  File "/home/airflow/.local/lib/python3.7/site-packages/pandas/core/frame.py", line 3458, in __getitem__
    indexer = self.columns.get_loc(key)
  File "/home/airflow/.local/lib/python3.7/site-packages/pandas/core/indexes/base.py", line 3363, in get_loc
    raise KeyError(key) from err
KeyError: 'artist_genres'
[2024-09-30T09:48:25.478+0000] {taskinstance.py:1323} INFO - Marking task as FAILED. dag_id=music_recommendation_system, task_id=create_user_genre_matrix, execution_date=20240930T094216, start_date=20240930T094824, end_date=20240930T094825
[2024-09-30T09:48:25.489+0000] {logging_mixin.py:137} INFO - Exception: Traceback (most recent call last):
  File "/home/***/.local/lib/python3.7/site-packages/pandas/core/indexes/base.py", line 3361, in get_loc
    return self._engine.get_loc(casted_key)
  File "pandas/_libs/index.pyx", line 76, in pandas._libs.index.IndexEngine.get_loc
  File "pandas/_libs/index.pyx", line 108, in pandas._libs.index.IndexEngine.get_loc
  File "pandas/_libs/hashtable_class_helper.pxi", line 5198, in pandas._libs.hashtable.PyObjectHashTable.get_item
  File "pandas/_libs/hashtable_class_helper.pxi", line 5206, in pandas._libs.hashtable.PyObjectHashTable.get_item
KeyError: 'artist_genres'

The above exception was the direct cause of the following exception:

Traceback (most recent call last):
  File "/home/***/.local/lib/python3.7/site-packages/***/models/taskinstance.py", line 1374, in _run_raw_task
    self._execute_task_with_callbacks(context, test_mode)
  File "/home/***/.local/lib/python3.7/site-packages/***/models/taskinstance.py", line 1520, in _execute_task_with_callbacks
    result = self._execute_task(context, task_orig)
  File "/home/***/.local/lib/python3.7/site-packages/***/models/taskinstance.py", line 1581, in _execute_task
    result = execute_callable(context=context)
  File "/home/***/.local/lib/python3.7/site-packages/***/operators/python.py", line 175, in execute
    return_value = self.execute_callable()
  File "/home/***/.local/lib/python3.7/site-packages/***/operators/python.py", line 192, in execute_callable
    return self.python_callable(*self.op_args, **self.op_kwargs)
  File "/opt/***/dags/music_recommendation_retraining.py", line 79, in create_user_genre_matrix_task
    all_genres = set([genre for genres in df['artist_genres'] for genre in genres])
  File "/home/***/.local/lib/python3.7/site-packages/pandas/core/frame.py", line 3458, in __getitem__
    indexer = self.columns.get_loc(key)
  File "/home/***/.local/lib/python3.7/site-packages/pandas/core/indexes/base.py", line 3363, in get_loc
    raise KeyError(key) from err
KeyError: 'artist_genres'

During handling of the above exception, another exception occurred:

Traceback (most recent call last):
  File "/home/***/.local/lib/python3.7/site-packages/datahub_***_plugin/datahub_plugin_v22.py", line 238, in custom_on_failure_callback
    datahub_task_status_callback(context, status=InstanceRunResult.FAILURE)
  File "/home/***/.local/lib/python3.7/site-packages/datahub_***_plugin/datahub_plugin_v22.py", line 105, in datahub_task_status_callback
    DatahubGenericHook(config.datahub_conn_id).get_underlying_hook().make_emitter()
  File "/home/***/.local/lib/python3.7/site-packages/datahub_***_plugin/hooks/datahub.py", line 255, in get_underlying_hook
    conn = self.get_connection(self.datahub_conn_id)
  File "/home/***/.local/lib/python3.7/site-packages/***/hooks/base.py", line 72, in get_connection
    conn = Connection.get_connection_from_secrets(conn_id)
  File "/home/***/.local/lib/python3.7/site-packages/***/models/connection.py", line 435, in get_connection_from_secrets
    raise AirflowNotFoundException(f"The conn_id `{conn_id}` isn't defined")
***.exceptions.AirflowNotFoundException: The conn_id `datahub_rest_default` isn't defined
[2024-09-30T09:48:25.511+0000] {standard_task_runner.py:105} ERROR - Failed to execute job 138 for task create_user_genre_matrix ('artist_genres'; 1507)
[2024-09-30T09:48:25.558+0000] {local_task_job.py:208} INFO - Task exited with return code 1
[2024-09-30T09:48:25.602+0000] {taskinstance.py:2578} INFO - 0 downstream tasks scheduled from follow-on schedule check
