[2024-09-30T10:32:46.922+0000] {taskinstance.py:1083} INFO - Dependencies all met for <TaskInstance: music_recommendation_system.train_and_evaluate_model scheduled__2024-09-30T10:15:12.691470+00:00 [queued]>
[2024-09-30T10:32:46.944+0000] {taskinstance.py:1083} INFO - Dependencies all met for <TaskInstance: music_recommendation_system.train_and_evaluate_model scheduled__2024-09-30T10:15:12.691470+00:00 [queued]>
[2024-09-30T10:32:46.945+0000] {taskinstance.py:1279} INFO - 
--------------------------------------------------------------------------------
[2024-09-30T10:32:46.945+0000] {taskinstance.py:1280} INFO - Starting attempt 2 of 2
[2024-09-30T10:32:46.946+0000] {taskinstance.py:1281} INFO - 
--------------------------------------------------------------------------------
[2024-09-30T10:32:46.976+0000] {taskinstance.py:1300} INFO - Executing <Task(PythonOperator): train_and_evaluate_model> on 2024-09-30 10:15:12.691470+00:00
[2024-09-30T10:32:46.993+0000] {standard_task_runner.py:55} INFO - Started process 2546 to run task
[2024-09-30T10:32:46.998+0000] {standard_task_runner.py:82} INFO - Running: ['***', 'tasks', 'run', 'music_recommendation_system', 'train_and_evaluate_model', 'scheduled__2024-09-30T10:15:12.691470+00:00', '--job-id', '321', '--raw', '--subdir', 'DAGS_FOLDER/music_recommendation_retraining.py', '--cfg-path', '/tmp/tmpnn11_126']
[2024-09-30T10:32:47.001+0000] {standard_task_runner.py:83} INFO - Job 321: Subtask train_and_evaluate_model
[2024-09-30T10:32:47.028+0000] {logging_mixin.py:137} WARNING - /home/***/.local/lib/python3.7/site-packages/***/settings.py:249 DeprecationWarning: The sql_alchemy_conn option in [core] has been moved to the sql_alchemy_conn option in [database] - the old setting has been used, but please update your config.
[2024-09-30T10:32:47.065+0000] {logging_mixin.py:137} WARNING - /home/***/.local/lib/python3.7/site-packages/***/utils/sqlalchemy.py:124 DeprecationWarning: The sql_alchemy_conn option in [core] has been moved to the sql_alchemy_conn option in [database] - the old setting has been used, but please update your config.
[2024-09-30T10:32:47.116+0000] {task_command.py:388} INFO - Running <TaskInstance: music_recommendation_system.train_and_evaluate_model scheduled__2024-09-30T10:15:12.691470+00:00 [running]> on host 1adfe0f4f205
[2024-09-30T10:32:47.247+0000] {taskinstance.py:1509} INFO - Exporting the following env vars:
AIRFLOW_CTX_DAG_OWNER=***
AIRFLOW_CTX_DAG_ID=music_recommendation_system
AIRFLOW_CTX_TASK_ID=train_and_evaluate_model
AIRFLOW_CTX_EXECUTION_DATE=2024-09-30T10:15:12.691470+00:00
AIRFLOW_CTX_TRY_NUMBER=2
AIRFLOW_CTX_DAG_RUN_ID=scheduled__2024-09-30T10:15:12.691470+00:00
[2024-09-30T10:32:47.441+0000] {logging_mixin.py:137} WARNING - 2024/09/30 10:32:47 INFO mlflow.tracking.fluent: Experiment with name 'Music_Recommendation_System' does not exist. Creating a new experiment.
[2024-09-30T10:32:47.840+0000] {logging_mixin.py:137} WARNING - 2024/09/30 10:32:47 WARNING mlflow.utils.git_utils: Failed to import Git (the Git executable is probably not on your PATH), so Git SHA is not available. Error: Failed to initialize: Bad git executable.
The git executable must be specified in one of the following ways:
    - be included in your $PATH
    - be set via $GIT_PYTHON_GIT_EXECUTABLE
    - explicitly set via git.refresh(<full-path-to-git-executable>)

All git commands will error until this is rectified.

This initial message can be silenced or aggravated in the future by setting the
$GIT_PYTHON_REFRESH environment variable. Use one of the following values:
    - quiet|q|silence|s|silent|none|n|0: for no message or exception
    - warn|w|warning|log|l|1: for a warning message (logging level CRITICAL, displayed by default)
    - error|e|exception|raise|r|2: for a raised exception

Example:
    export GIT_PYTHON_REFRESH=quiet
[2024-09-30T10:32:48.271+0000] {logging_mixin.py:137} INFO - Mean Squared Error: 168.1916779170685
[2024-09-30T10:32:48.294+0000] {python.py:177} INFO - Done. Returned value was: None
[2024-09-30T10:32:48.352+0000] {taskinstance.py:1323} INFO - Marking task as SUCCESS. dag_id=music_recommendation_system, task_id=train_and_evaluate_model, execution_date=20240930T101512, start_date=20240930T103246, end_date=20240930T103248
[2024-09-30T10:32:48.372+0000] {logging_mixin.py:137} INFO - Exception: Traceback (most recent call last):
  File "/home/***/.local/lib/python3.7/site-packages/datahub_***_plugin/datahub_plugin_v22.py", line 258, in custom_on_success_callback
    datahub_task_status_callback(context, status=InstanceRunResult.SUCCESS)
  File "/home/***/.local/lib/python3.7/site-packages/datahub_***_plugin/datahub_plugin_v22.py", line 105, in datahub_task_status_callback
    DatahubGenericHook(config.datahub_conn_id).get_underlying_hook().make_emitter()
  File "/home/***/.local/lib/python3.7/site-packages/datahub_***_plugin/hooks/datahub.py", line 255, in get_underlying_hook
    conn = self.get_connection(self.datahub_conn_id)
  File "/home/***/.local/lib/python3.7/site-packages/***/hooks/base.py", line 72, in get_connection
    conn = Connection.get_connection_from_secrets(conn_id)
  File "/home/***/.local/lib/python3.7/site-packages/***/models/connection.py", line 435, in get_connection_from_secrets
    raise AirflowNotFoundException(f"The conn_id `{conn_id}` isn't defined")
***.exceptions.AirflowNotFoundException: The conn_id `datahub_rest_default` isn't defined
[2024-09-30T10:32:48.457+0000] {local_task_job.py:208} INFO - Task exited with return code 0
[2024-09-30T10:32:48.490+0000] {taskinstance.py:2578} INFO - 0 downstream tasks scheduled from follow-on schedule check
