[2024-09-30T10:27:56.431+0000] {taskinstance.py:1083} INFO - Dependencies all met for <TaskInstance: music_recommendation_system.create_user_genre_matrix scheduled__2024-09-30T10:26:50.005014+00:00 [queued]>
[2024-09-30T10:27:56.451+0000] {taskinstance.py:1083} INFO - Dependencies all met for <TaskInstance: music_recommendation_system.create_user_genre_matrix scheduled__2024-09-30T10:26:50.005014+00:00 [queued]>
[2024-09-30T10:27:56.452+0000] {taskinstance.py:1279} INFO - 
--------------------------------------------------------------------------------
[2024-09-30T10:27:56.453+0000] {taskinstance.py:1280} INFO - Starting attempt 1 of 2
[2024-09-30T10:27:56.453+0000] {taskinstance.py:1281} INFO - 
--------------------------------------------------------------------------------
[2024-09-30T10:27:56.474+0000] {taskinstance.py:1300} INFO - Executing <Task(PythonOperator): create_user_genre_matrix> on 2024-09-30 10:26:50.005014+00:00
[2024-09-30T10:27:56.486+0000] {standard_task_runner.py:55} INFO - Started process 2411 to run task
[2024-09-30T10:27:56.489+0000] {standard_task_runner.py:82} INFO - Running: ['***', 'tasks', 'run', 'music_recommendation_system', 'create_user_genre_matrix', 'scheduled__2024-09-30T10:26:50.005014+00:00', '--job-id', '294', '--raw', '--subdir', 'DAGS_FOLDER/music_recommendation_retraining.py', '--cfg-path', '/tmp/tmp8m9s4h42']
[2024-09-30T10:27:56.491+0000] {standard_task_runner.py:83} INFO - Job 294: Subtask create_user_genre_matrix
[2024-09-30T10:27:56.512+0000] {logging_mixin.py:137} WARNING - /home/***/.local/lib/python3.7/site-packages/***/settings.py:249 DeprecationWarning: The sql_alchemy_conn option in [core] has been moved to the sql_alchemy_conn option in [database] - the old setting has been used, but please update your config.
[2024-09-30T10:27:56.534+0000] {logging_mixin.py:137} WARNING - /home/***/.local/lib/python3.7/site-packages/***/utils/sqlalchemy.py:124 DeprecationWarning: The sql_alchemy_conn option in [core] has been moved to the sql_alchemy_conn option in [database] - the old setting has been used, but please update your config.
[2024-09-30T10:27:56.567+0000] {task_command.py:388} INFO - Running <TaskInstance: music_recommendation_system.create_user_genre_matrix scheduled__2024-09-30T10:26:50.005014+00:00 [running]> on host 1adfe0f4f205
[2024-09-30T10:27:56.651+0000] {taskinstance.py:1509} INFO - Exporting the following env vars:
AIRFLOW_CTX_DAG_OWNER=***
AIRFLOW_CTX_DAG_ID=music_recommendation_system
AIRFLOW_CTX_TASK_ID=create_user_genre_matrix
AIRFLOW_CTX_EXECUTION_DATE=2024-09-30T10:26:50.005014+00:00
AIRFLOW_CTX_TRY_NUMBER=1
AIRFLOW_CTX_DAG_RUN_ID=scheduled__2024-09-30T10:26:50.005014+00:00
[2024-09-30T10:33:27.642+0000] {local_task_job.py:112} ERROR - Received SIGTERM. Terminating subprocesses
[2024-09-30T10:33:27.672+0000] {process_utils.py:133} INFO - Sending Signals.SIGTERM to group 2411. PIDs of all processes in the group: [2411]
[2024-09-30T10:33:27.674+0000] {process_utils.py:84} INFO - Sending the signal Signals.SIGTERM to group 2411
[2024-09-30T10:33:27.677+0000] {taskinstance.py:1479} ERROR - Received SIGTERM. Terminating subprocesses.
[2024-09-30T10:33:27.751+0000] {taskinstance.py:1768} ERROR - Task failed with exception
Traceback (most recent call last):
  File "/home/airflow/.local/lib/python3.7/site-packages/airflow/operators/python.py", line 175, in execute
    return_value = self.execute_callable()
  File "/home/airflow/.local/lib/python3.7/site-packages/airflow/operators/python.py", line 192, in execute_callable
    return self.python_callable(*self.op_args, **self.op_kwargs)
  File "/opt/airflow/dags/music_recommendation_retraining.py", line 80, in create_user_genre_matrix_task
    all_genres = set([genre for genres in df['artist_genres'] for genre in genres])
  File "/opt/airflow/dags/music_recommendation_retraining.py", line 23, in create_user_genre_matrix
    for genre in all_genres:
  File "/home/airflow/.local/lib/python3.7/site-packages/pandas/core/series.py", line 4357, in apply
    return SeriesApply(self, func, convert_dtype, args, kwargs).apply()
  File "/home/airflow/.local/lib/python3.7/site-packages/pandas/core/apply.py", line 1043, in apply
    return self.apply_standard()
  File "/home/airflow/.local/lib/python3.7/site-packages/pandas/core/apply.py", line 1092, in apply_standard
    values = obj.astype(object)._values
  File "/home/airflow/.local/lib/python3.7/site-packages/pandas/core/generic.py", line 5815, in astype
    new_data = self._mgr.astype(dtype=dtype, copy=copy, errors=errors)
  File "/home/airflow/.local/lib/python3.7/site-packages/pandas/core/internals/managers.py", line 418, in astype
    return self.apply("astype", dtype=dtype, copy=copy, errors=errors)
  File "/home/airflow/.local/lib/python3.7/site-packages/pandas/core/internals/managers.py", line 327, in apply
    applied = getattr(b, f)(**kwargs)
  File "/home/airflow/.local/lib/python3.7/site-packages/pandas/core/internals/blocks.py", line 594, in astype
    newb = self.make_block(new_values)
  File "/home/airflow/.local/lib/python3.7/site-packages/pandas/core/internals/blocks.py", line 259, in make_block
    return new_block(values, placement=placement, ndim=self.ndim)
  File "/home/airflow/.local/lib/python3.7/site-packages/pandas/core/internals/blocks.py", line 1942, in new_block
    values = maybe_coerce_values(values)
  File "/home/airflow/.local/lib/python3.7/site-packages/pandas/core/internals/blocks.py", line 1878, in maybe_coerce_values
    values = ensure_wrapped_if_datetimelike(values)
  File "/home/airflow/.local/lib/python3.7/site-packages/pandas/core/construction.py", line 435, in ensure_wrapped_if_datetimelike
    if isinstance(arr, np.ndarray):
  File "/home/airflow/.local/lib/python3.7/site-packages/airflow/models/taskinstance.py", line 1481, in signal_handler
    raise AirflowException("Task received SIGTERM signal")
airflow.exceptions.AirflowException: Task received SIGTERM signal
[2024-09-30T10:33:27.802+0000] {taskinstance.py:1323} INFO - Marking task as UP_FOR_RETRY. dag_id=music_recommendation_system, task_id=create_user_genre_matrix, execution_date=20240930T102650, start_date=20240930T102756, end_date=20240930T103327
[2024-09-30T10:33:27.831+0000] {logging_mixin.py:137} INFO - Exception: Traceback (most recent call last):
  File "/home/***/.local/lib/python3.7/site-packages/***/models/taskinstance.py", line 1374, in _run_raw_task
    self._execute_task_with_callbacks(context, test_mode)
  File "/home/***/.local/lib/python3.7/site-packages/***/models/taskinstance.py", line 1520, in _execute_task_with_callbacks
    result = self._execute_task(context, task_orig)
  File "/home/***/.local/lib/python3.7/site-packages/***/models/taskinstance.py", line 1581, in _execute_task
    result = execute_callable(context=context)
  File "/home/***/.local/lib/python3.7/site-packages/***/operators/python.py", line 175, in execute
    return_value = self.execute_callable()
  File "/home/***/.local/lib/python3.7/site-packages/***/operators/python.py", line 192, in execute_callable
    return self.python_callable(*self.op_args, **self.op_kwargs)
  File "/opt/***/dags/music_recommendation_retraining.py", line 80, in create_user_genre_matrix_task
    all_genres = set([genre for genres in df['artist_genres'] for genre in genres])
  File "/opt/***/dags/music_recommendation_retraining.py", line 23, in create_user_genre_matrix
    for genre in all_genres:
  File "/home/***/.local/lib/python3.7/site-packages/pandas/core/series.py", line 4357, in apply
    return SeriesApply(self, func, convert_dtype, args, kwargs).apply()
  File "/home/***/.local/lib/python3.7/site-packages/pandas/core/apply.py", line 1043, in apply
    return self.apply_standard()
  File "/home/***/.local/lib/python3.7/site-packages/pandas/core/apply.py", line 1092, in apply_standard
    values = obj.astype(object)._values
  File "/home/***/.local/lib/python3.7/site-packages/pandas/core/generic.py", line 5815, in astype
    new_data = self._mgr.astype(dtype=dtype, copy=copy, errors=errors)
  File "/home/***/.local/lib/python3.7/site-packages/pandas/core/internals/managers.py", line 418, in astype
    return self.apply("astype", dtype=dtype, copy=copy, errors=errors)
  File "/home/***/.local/lib/python3.7/site-packages/pandas/core/internals/managers.py", line 327, in apply
    applied = getattr(b, f)(**kwargs)
  File "/home/***/.local/lib/python3.7/site-packages/pandas/core/internals/blocks.py", line 594, in astype
    newb = self.make_block(new_values)
  File "/home/***/.local/lib/python3.7/site-packages/pandas/core/internals/blocks.py", line 259, in make_block
    return new_block(values, placement=placement, ndim=self.ndim)
  File "/home/***/.local/lib/python3.7/site-packages/pandas/core/internals/blocks.py", line 1942, in new_block
    values = maybe_coerce_values(values)
  File "/home/***/.local/lib/python3.7/site-packages/pandas/core/internals/blocks.py", line 1878, in maybe_coerce_values
    values = ensure_wrapped_if_datetimelike(values)
  File "/home/***/.local/lib/python3.7/site-packages/pandas/core/construction.py", line 435, in ensure_wrapped_if_datetimelike
    if isinstance(arr, np.ndarray):
  File "/home/***/.local/lib/python3.7/site-packages/***/models/taskinstance.py", line 1481, in signal_handler
    raise AirflowException("Task received SIGTERM signal")
***.exceptions.AirflowException: Task received SIGTERM signal

During handling of the above exception, another exception occurred:

Traceback (most recent call last):
  File "/home/***/.local/lib/python3.7/site-packages/datahub_***_plugin/datahub_plugin_v22.py", line 279, in custom_on_retry_callback
    context, status=InstanceRunResult.UP_FOR_RETRY
  File "/home/***/.local/lib/python3.7/site-packages/datahub_***_plugin/datahub_plugin_v22.py", line 105, in datahub_task_status_callback
    DatahubGenericHook(config.datahub_conn_id).get_underlying_hook().make_emitter()
  File "/home/***/.local/lib/python3.7/site-packages/datahub_***_plugin/hooks/datahub.py", line 255, in get_underlying_hook
    conn = self.get_connection(self.datahub_conn_id)
  File "/home/***/.local/lib/python3.7/site-packages/***/hooks/base.py", line 72, in get_connection
    conn = Connection.get_connection_from_secrets(conn_id)
  File "/home/***/.local/lib/python3.7/site-packages/***/models/connection.py", line 435, in get_connection_from_secrets
    raise AirflowNotFoundException(f"The conn_id `{conn_id}` isn't defined")
***.exceptions.AirflowNotFoundException: The conn_id `datahub_rest_default` isn't defined
[2024-09-30T10:33:27.893+0000] {standard_task_runner.py:105} ERROR - Failed to execute job 294 for task create_user_genre_matrix (Task received SIGTERM signal; 2411)
[2024-09-30T10:33:27.972+0000] {process_utils.py:79} INFO - Process psutil.Process(pid=2411, status='terminated', exitcode=1, started='10:27:56') (2411) terminated with exit code 1
[2024-09-30T10:33:27.973+0000] {local_task_job.py:208} INFO - Task exited with return code 143
[2024-09-30T10:33:28.031+0000] {taskinstance.py:2578} INFO - 0 downstream tasks scheduled from follow-on schedule check
[2024-09-30T10:33:30.483+0000] {local_task_job.py:112} ERROR - Received SIGTERM. Terminating subprocesses
[2024-09-30T10:33:30.484+0000] {local_task_job.py:208} INFO - Task exited with return code 143
