[2024-09-30T11:09:01.126+0000] {taskinstance.py:1083} INFO - Dependencies all met for <TaskInstance: music_recommendation_system.create_user_genre_matrix scheduled__2024-09-30T11:07:54.677290+00:00 [queued]>
[2024-09-30T11:09:01.140+0000] {taskinstance.py:1083} INFO - Dependencies all met for <TaskInstance: music_recommendation_system.create_user_genre_matrix scheduled__2024-09-30T11:07:54.677290+00:00 [queued]>
[2024-09-30T11:09:01.140+0000] {taskinstance.py:1279} INFO - 
--------------------------------------------------------------------------------
[2024-09-30T11:09:01.141+0000] {taskinstance.py:1280} INFO - Starting attempt 1 of 2
[2024-09-30T11:09:01.142+0000] {taskinstance.py:1281} INFO - 
--------------------------------------------------------------------------------
[2024-09-30T11:09:01.164+0000] {taskinstance.py:1300} INFO - Executing <Task(PythonOperator): create_user_genre_matrix> on 2024-09-30 11:07:54.677290+00:00
[2024-09-30T11:09:01.174+0000] {standard_task_runner.py:55} INFO - Started process 733 to run task
[2024-09-30T11:09:01.177+0000] {standard_task_runner.py:82} INFO - Running: ['***', 'tasks', 'run', 'music_recommendation_system', 'create_user_genre_matrix', 'scheduled__2024-09-30T11:07:54.677290+00:00', '--job-id', '404', '--raw', '--subdir', 'DAGS_FOLDER/music_recommendation_retraining.py', '--cfg-path', '/tmp/tmpat6jqpm5']
[2024-09-30T11:09:01.179+0000] {standard_task_runner.py:83} INFO - Job 404: Subtask create_user_genre_matrix
[2024-09-30T11:09:01.198+0000] {logging_mixin.py:137} WARNING - /home/***/.local/lib/python3.7/site-packages/***/settings.py:249 DeprecationWarning: The sql_alchemy_conn option in [core] has been moved to the sql_alchemy_conn option in [database] - the old setting has been used, but please update your config.
[2024-09-30T11:09:01.220+0000] {logging_mixin.py:137} WARNING - /home/***/.local/lib/python3.7/site-packages/***/utils/sqlalchemy.py:124 DeprecationWarning: The sql_alchemy_conn option in [core] has been moved to the sql_alchemy_conn option in [database] - the old setting has been used, but please update your config.
[2024-09-30T11:09:01.259+0000] {task_command.py:388} INFO - Running <TaskInstance: music_recommendation_system.create_user_genre_matrix scheduled__2024-09-30T11:07:54.677290+00:00 [running]> on host cdcd403e68a1
[2024-09-30T11:09:01.348+0000] {taskinstance.py:1509} INFO - Exporting the following env vars:
AIRFLOW_CTX_DAG_OWNER=***
AIRFLOW_CTX_DAG_ID=music_recommendation_system
AIRFLOW_CTX_TASK_ID=create_user_genre_matrix
AIRFLOW_CTX_EXECUTION_DATE=2024-09-30T11:07:54.677290+00:00
AIRFLOW_CTX_TRY_NUMBER=1
AIRFLOW_CTX_DAG_RUN_ID=scheduled__2024-09-30T11:07:54.677290+00:00
[2024-09-30T11:15:46.853+0000] {local_task_job.py:112} ERROR - Received SIGTERM. Terminating subprocesses
[2024-09-30T11:15:46.948+0000] {process_utils.py:133} INFO - Sending Signals.SIGTERM to group 733. PIDs of all processes in the group: [733]
[2024-09-30T11:15:46.950+0000] {process_utils.py:84} INFO - Sending the signal Signals.SIGTERM to group 733
[2024-09-30T11:15:46.956+0000] {taskinstance.py:1479} ERROR - Received SIGTERM. Terminating subprocesses.
[2024-09-30T11:15:47.069+0000] {taskinstance.py:1768} ERROR - Task failed with exception
Traceback (most recent call last):
  File "/home/airflow/.local/lib/python3.7/site-packages/airflow/operators/python.py", line 175, in execute
    return_value = self.execute_callable()
  File "/home/airflow/.local/lib/python3.7/site-packages/airflow/operators/python.py", line 192, in execute_callable
    return self.python_callable(*self.op_args, **self.op_kwargs)
  File "/opt/airflow/dags/music_recommendation_retraining.py", line 81, in create_user_genre_matrix_task
    all_genres = set([genre for genres in df['artist_genres'] for genre in genres])
  File "/opt/airflow/dags/music_recommendation_retraining.py", line 24, in create_user_genre_matrix
    for genre in all_genres:
  File "/home/airflow/.local/lib/python3.7/site-packages/pandas/core/frame.py", line 3448, in __getitem__
    if com.is_bool_indexer(key):
  File "/home/airflow/.local/lib/python3.7/site-packages/pandas/core/common.py", line 131, in is_bool_indexer
    if key.dtype == np.object_:
  File "/home/airflow/.local/lib/python3.7/site-packages/pandas/core/series.py", line 567, in dtype
    return self._mgr.dtype
  File "/home/airflow/.local/lib/python3.7/site-packages/airflow/models/taskinstance.py", line 1481, in signal_handler
    raise AirflowException("Task received SIGTERM signal")
airflow.exceptions.AirflowException: Task received SIGTERM signal
[2024-09-30T11:15:47.102+0000] {taskinstance.py:1323} INFO - Marking task as UP_FOR_RETRY. dag_id=music_recommendation_system, task_id=create_user_genre_matrix, execution_date=20240930T110754, start_date=20240930T110901, end_date=20240930T111547
[2024-09-30T11:15:47.120+0000] {logging_mixin.py:137} INFO - Exception: Traceback (most recent call last):
  File "/home/***/.local/lib/python3.7/site-packages/***/models/taskinstance.py", line 1374, in _run_raw_task
    self._execute_task_with_callbacks(context, test_mode)
  File "/home/***/.local/lib/python3.7/site-packages/***/models/taskinstance.py", line 1520, in _execute_task_with_callbacks
    result = self._execute_task(context, task_orig)
  File "/home/***/.local/lib/python3.7/site-packages/***/models/taskinstance.py", line 1581, in _execute_task
    result = execute_callable(context=context)
  File "/home/***/.local/lib/python3.7/site-packages/***/operators/python.py", line 175, in execute
    return_value = self.execute_callable()
  File "/home/***/.local/lib/python3.7/site-packages/***/operators/python.py", line 192, in execute_callable
    return self.python_callable(*self.op_args, **self.op_kwargs)
  File "/opt/***/dags/music_recommendation_retraining.py", line 81, in create_user_genre_matrix_task
    all_genres = set([genre for genres in df['artist_genres'] for genre in genres])
  File "/opt/***/dags/music_recommendation_retraining.py", line 24, in create_user_genre_matrix
    for genre in all_genres:
  File "/home/***/.local/lib/python3.7/site-packages/pandas/core/frame.py", line 3448, in __getitem__
    if com.is_bool_indexer(key):
  File "/home/***/.local/lib/python3.7/site-packages/pandas/core/common.py", line 131, in is_bool_indexer
    if key.dtype == np.object_:
  File "/home/***/.local/lib/python3.7/site-packages/pandas/core/series.py", line 567, in dtype
    return self._mgr.dtype
  File "/home/***/.local/lib/python3.7/site-packages/***/models/taskinstance.py", line 1481, in signal_handler
    raise AirflowException("Task received SIGTERM signal")
***.exceptions.AirflowException: Task received SIGTERM signal

During handling of the above exception, another exception occurred:

Traceback (most recent call last):
  File "/home/***/.local/lib/python3.7/site-packages/datahub_***_plugin/datahub_plugin_v22.py", line 279, in custom_on_retry_callback
    context, status=InstanceRunResult.UP_FOR_RETRY
  File "/home/***/.local/lib/python3.7/site-packages/datahub_***_plugin/datahub_plugin_v22.py", line 105, in datahub_task_status_callback
    DatahubGenericHook(config.datahub_conn_id).get_underlying_hook().make_emitter()
  File "/home/***/.local/lib/python3.7/site-packages/datahub_***_plugin/hooks/datahub.py", line 255, in get_underlying_hook
    conn = self.get_connection(self.datahub_conn_id)
  File "/home/***/.local/lib/python3.7/site-packages/***/hooks/base.py", line 72, in get_connection
    conn = Connection.get_connection_from_secrets(conn_id)
  File "/home/***/.local/lib/python3.7/site-packages/***/models/connection.py", line 435, in get_connection_from_secrets
    raise AirflowNotFoundException(f"The conn_id `{conn_id}` isn't defined")
***.exceptions.AirflowNotFoundException: The conn_id `datahub_rest_default` isn't defined
[2024-09-30T11:15:48.899+0000] {standard_task_runner.py:105} ERROR - Failed to execute job 404 for task create_user_genre_matrix (Task received SIGTERM signal; 733)
[2024-09-30T11:15:48.988+0000] {process_utils.py:79} INFO - Process psutil.Process(pid=733, status='terminated', exitcode=1, started='11:09:01') (733) terminated with exit code 1
[2024-09-30T11:15:48.991+0000] {local_task_job.py:208} INFO - Task exited with return code 143
[2024-09-30T11:15:49.113+0000] {taskinstance.py:2578} INFO - 0 downstream tasks scheduled from follow-on schedule check
