[2024-09-30T11:40:27.611+0000] {logging_mixin.py:150} WARNING - /home/***/.local/lib/python3.9/site-packages/***/utils/sqlalchemy.py:124 DeprecationWarning: The sql_alchemy_conn option in [core] has been moved to the sql_alchemy_conn option in [database] - the old setting has been used, but please update your config.
[2024-09-30T11:40:28.214+0000] {taskinstance.py:1103} INFO - Dependencies all met for dep_context=non-requeueable deps ti=<TaskInstance: music_recommendation_system.train_and_evaluate_model scheduled__2024-09-30T11:11:30.292045+00:00 [queued]>
[2024-09-30T11:40:28.243+0000] {taskinstance.py:1103} INFO - Dependencies all met for dep_context=requeueable deps ti=<TaskInstance: music_recommendation_system.train_and_evaluate_model scheduled__2024-09-30T11:11:30.292045+00:00 [queued]>
[2024-09-30T11:40:28.244+0000] {taskinstance.py:1308} INFO - Starting attempt 1 of 2
[2024-09-30T11:40:28.275+0000] {taskinstance.py:1327} INFO - Executing <Task(PythonOperator): train_and_evaluate_model> on 2024-09-30 11:11:30.292045+00:00
[2024-09-30T11:40:28.295+0000] {standard_task_runner.py:57} INFO - Started process 1384 to run task
[2024-09-30T11:40:28.300+0000] {standard_task_runner.py:84} INFO - Running: ['***', 'tasks', 'run', 'music_recommendation_system', 'train_and_evaluate_model', 'scheduled__2024-09-30T11:11:30.292045+00:00', '--job-id', '456', '--raw', '--subdir', 'DAGS_FOLDER/music_recommendation_retraining.py', '--cfg-path', '/tmp/tmpwheizej_']
[2024-09-30T11:40:28.308+0000] {standard_task_runner.py:85} INFO - Job 456: Subtask train_and_evaluate_model
[2024-09-30T11:40:28.340+0000] {logging_mixin.py:150} WARNING - /home/***/.local/lib/python3.9/site-packages/***/settings.py:195 DeprecationWarning: The sql_alchemy_conn option in [core] has been moved to the sql_alchemy_conn option in [database] - the old setting has been used, but please update your config.
[2024-09-30T11:40:28.429+0000] {task_command.py:410} INFO - Running <TaskInstance: music_recommendation_system.train_and_evaluate_model scheduled__2024-09-30T11:11:30.292045+00:00 [running]> on host 726d734aff16
[2024-09-30T11:40:28.447+0000] {logging_mixin.py:150} WARNING - /home/***/.local/lib/python3.9/site-packages/***/utils/sqlalchemy.py:124 DeprecationWarning: The sql_alchemy_conn option in [core] has been moved to the sql_alchemy_conn option in [database] - the old setting has been used, but please update your config.
[2024-09-30T11:40:28.623+0000] {taskinstance.py:1545} INFO - Exporting env vars: AIRFLOW_CTX_DAG_OWNER='***' AIRFLOW_CTX_DAG_ID='music_recommendation_system' AIRFLOW_CTX_TASK_ID='train_and_evaluate_model' AIRFLOW_CTX_EXECUTION_DATE='2024-09-30T11:11:30.292045+00:00' AIRFLOW_CTX_TRY_NUMBER='1' AIRFLOW_CTX_DAG_RUN_ID='scheduled__2024-09-30T11:11:30.292045+00:00'
[2024-09-30T11:40:29.161+0000] {logging_mixin.py:150} WARNING - 2024/09/30 11:40:29 WARNING mlflow.utils.git_utils: Failed to import Git (the Git executable is probably not on your PATH), so Git SHA is not available. Error: Failed to initialize: Bad git executable.
The git executable must be specified in one of the following ways:
    - be included in your $PATH
    - be set via $GIT_PYTHON_GIT_EXECUTABLE
    - explicitly set via git.refresh(<full-path-to-git-executable>)

All git commands will error until this is rectified.

This initial message can be silenced or aggravated in the future by setting the
$GIT_PYTHON_REFRESH environment variable. Use one of the following values:
    - quiet|q|silence|s|silent|none|n|0: for no message or exception
    - warn|w|warning|log|l|1: for a warning message (logging level CRITICAL, displayed by default)
    - error|e|exception|raise|r|2: for a raised exception

Example:
    export GIT_PYTHON_REFRESH=quiet
[2024-09-30T11:40:29.511+0000] {logging_mixin.py:150} INFO - Mean Squared Error: 168.828106075217
[2024-09-30T11:40:29.866+0000] {logging_mixin.py:150} WARNING - 2024/09/30 11:40:29 INFO mlflow.tracking._tracking_service.client: üèÉ View run painted-shrike-147 at: http://mlflow:5000/#/experiments/857329589221019809/runs/d392f4e51c1548a8a43d1c994cfdbb76.
[2024-09-30T11:40:29.867+0000] {logging_mixin.py:150} WARNING - 2024/09/30 11:40:29 INFO mlflow.tracking._tracking_service.client: üß™ View experiment at: http://mlflow:5000/#/experiments/857329589221019809.
[2024-09-30T11:40:29.900+0000] {python.py:183} INFO - Done. Returned value was: None
[2024-09-30T11:40:29.922+0000] {taskinstance.py:1345} INFO - Marking task as SUCCESS. dag_id=music_recommendation_system, task_id=train_and_evaluate_model, execution_date=20240930T111130, start_date=20240930T114028, end_date=20240930T114029
[2024-09-30T11:40:29.936+0000] {base.py:73} INFO - Using connection ID 'datahub_rest_default' for task execution.
[2024-09-30T11:40:29.938+0000] {base.py:73} INFO - Using connection ID 'datahub_rest_default' for task execution.
[2024-09-30T11:40:29.941+0000] {datahub_plugin_v22.py:112} INFO - Emitting Datahub Dataflow: DataFlow(urn=DataFlowUrn(urn:li:dataFlow:(***,music_recommendation_system,prod)), id='music_recommendation_system', orchestrator='***', cluster=None, name=None, description='A DAG to train and log a music recommendation system', properties={'_access_control': 'None', 'catchup': 'False', 'description': "'A DAG to train and log a music recommendation system'", 'doc_md': 'None', 'fileloc': "'/opt/***/dags/music_recommendation_retraining.py'", 'is_paused_upon_creation': 'None', 'start_date': 'None', 'tags': '[]', 'timezone': "Timezone('UTC')"}, url='http://localhost:8080/tree?dag_id=music_recommendation_system', tags=set(), owners={'***'}, group_owners=set(), platform_instance=None, env='prod')
[2024-09-30T11:40:29.945+0000] {datahub_plugin_v22.py:88} ERROR - Error sending metadata to datahub: ('Unable to emit metadata to DataHub GMS', {'message': "No connection adapters were found for 'datahub:8080/aspects?action=ingestProposal'"})
Traceback (most recent call last):
  File "/home/airflow/.local/lib/python3.9/site-packages/datahub/emitter/rest_emitter.py", line 325, in _emit_generic
    response = self._session.post(url, data=payload)
  File "/home/airflow/.local/lib/python3.9/site-packages/requests/sessions.py", line 637, in post
    return self.request("POST", url, data=data, json=json, **kwargs)
  File "/home/airflow/.local/lib/python3.9/site-packages/requests/sessions.py", line 589, in request
    resp = self.send(prep, **send_kwargs)
  File "/home/airflow/.local/lib/python3.9/site-packages/requests/sessions.py", line 697, in send
    adapter = self.get_adapter(url=request.url)
  File "/home/airflow/.local/lib/python3.9/site-packages/requests/sessions.py", line 794, in get_adapter
    raise InvalidSchema(f"No connection adapters were found for {url!r}")
requests.exceptions.InvalidSchema: No connection adapters were found for 'datahub:8080/aspects?action=ingestProposal'

The above exception was the direct cause of the following exception:

Traceback (most recent call last):
  File "/home/airflow/.local/lib/python3.9/site-packages/datahub/emitter/rest_emitter.py", line 222, in emit
    self.emit_mcp(item, async_flag=async_flag)
  File "/home/airflow/.local/lib/python3.9/site-packages/datahub/emitter/rest_emitter.py", line 269, in emit_mcp
    self._emit_generic(url, payload)
  File "/home/airflow/.local/lib/python3.9/site-packages/datahub/emitter/rest_emitter.py", line 353, in _emit_generic
    raise OperationalError(
datahub.configuration.common.OperationalError: ('Unable to emit metadata to DataHub GMS', {'message': "No connection adapters were found for 'datahub:8080/aspects?action=ingestProposal'"})
[2024-09-30T11:40:29.949+0000] {logging_mixin.py:150} INFO - Exception: Traceback (most recent call last):
  File "/home/***/.local/lib/python3.9/site-packages/datahub/emitter/rest_emitter.py", line 325, in _emit_generic
    response = self._session.post(url, data=payload)
  File "/home/***/.local/lib/python3.9/site-packages/requests/sessions.py", line 637, in post
    return self.request("POST", url, data=data, json=json, **kwargs)
  File "/home/***/.local/lib/python3.9/site-packages/requests/sessions.py", line 589, in request
    resp = self.send(prep, **send_kwargs)
  File "/home/***/.local/lib/python3.9/site-packages/requests/sessions.py", line 697, in send
    adapter = self.get_adapter(url=request.url)
  File "/home/***/.local/lib/python3.9/site-packages/requests/sessions.py", line 794, in get_adapter
    raise InvalidSchema(f"No connection adapters were found for {url!r}")
requests.exceptions.InvalidSchema: No connection adapters were found for 'datahub:8080/aspects?action=ingestProposal'

The above exception was the direct cause of the following exception:

Traceback (most recent call last):
  File "/home/***/.local/lib/python3.9/site-packages/datahub_***_plugin/datahub_plugin_v22.py", line 260, in custom_on_success_callback
    datahub_task_status_callback(context, status=InstanceRunResult.SUCCESS)
  File "/home/***/.local/lib/python3.9/site-packages/datahub_***_plugin/datahub_plugin_v22.py", line 113, in datahub_task_status_callback
    dataflow.emit(emitter, callback=_make_emit_callback(task.log))
  File "/home/***/.local/lib/python3.9/site-packages/datahub/api/entities/datajob/dataflow.py", line 195, in emit
    emitter.emit(mcp, callback)
  File "/home/***/.local/lib/python3.9/site-packages/datahub/emitter/rest_emitter.py", line 222, in emit
    self.emit_mcp(item, async_flag=async_flag)
  File "/home/***/.local/lib/python3.9/site-packages/datahub/emitter/rest_emitter.py", line 269, in emit_mcp
    self._emit_generic(url, payload)
  File "/home/***/.local/lib/python3.9/site-packages/datahub/emitter/rest_emitter.py", line 353, in _emit_generic
    raise OperationalError(
datahub.configuration.common.OperationalError: ('Unable to emit metadata to DataHub GMS', {'message': "No connection adapters were found for 'datahub:8080/aspects?action=ingestProposal'"})
[2024-09-30T11:40:30.046+0000] {local_task_job_runner.py:225} INFO - Task exited with return code 0
[2024-09-30T11:40:30.316+0000] {taskinstance.py:2653} INFO - 0 downstream tasks scheduled from follow-on schedule check
